<?xml version="1.0"?>
<robot name="my_nav2_robot">

  <!-- ==================== MATERIALS ==================== -->

  <material name="green">
    <color rgba="0.2 0.7 0.3 1.0"/>
  </material>

  <material name="black">
    <color rgba="0.1 0.1 0.1 1.0"/>
  </material>

  <material name="blue">
    <color rgba="0.0 0.0 0.8 1.0"/>
  </material>


  <!-- ==================== BASE ==================== -->

  <link name="base_footprint"/>

  <joint name="base_footprint_joint" type="fixed">
    <parent link="base_footprint"/>
    <child link="base_link"/>
    <origin xyz="0 0 0.1" rpy="0 0 0"/>
  </joint>

  <link name="base_link">
    <inertial>
      <mass value="2.0"/>
      <origin xyz="0 0 0" rpy="0 0 0"/>
      <inertia ixx="0.015" ixy="0.0" ixz="0.0"
                            iyy="0.037" iyz="0.0"
                                        izz="0.037"/>
    </inertial>
    <visual>
      <geometry>
        <box size="0.4 0.3 0.1"/>
      </geometry>
      <material name="green"/>
    </visual>
    <collision>
      <geometry>
        <box size="0.4 0.3 0.1"/>
      </geometry>
    </collision>
  </link>


  <!-- ==================== WHEELS ==================== -->

  <!-- Left Wheel -->
  <link name="left_wheel">
    <inertial>
      <mass value="0.5"/>
      <inertia ixx="0.001" ixy="0.0" ixz="0.0"
                            iyy="0.001" iyz="0.0"
                                        izz="0.001"/>
    </inertial>
    <visual>
      <geometry>
        <cylinder radius="0.1" length="0.05"/>
      </geometry>
      <material name="black"/>
    </visual>
    <collision>
      <geometry>
        <cylinder radius="0.1" length="0.05"/>
      </geometry>
    </collision>
  </link>

  <joint name="left_wheel_joint" type="continuous">
    <parent link="base_link"/>
    <child link="left_wheel"/>
    <origin xyz="-0.1 0.175 0" rpy="-1.5708 0 0"/>
    <axis xyz="0 0 1"/>
  </joint>

  <!-- Right Wheel -->
  <link name="right_wheel">
    <inertial>
      <mass value="0.5"/>
      <inertia ixx="0.001" ixy="0.0" ixz="0.0"
                            iyy="0.001" iyz="0.0"
                                        izz="0.001"/>
    </inertial>
    <visual>
      <geometry>
        <cylinder radius="0.1" length="0.05"/>
      </geometry>
      <material name="black"/>
    </visual>
    <collision>
      <geometry>
        <cylinder radius="0.1" length="0.05"/>
      </geometry>
    </collision>
  </link>

  <joint name="right_wheel_joint" type="continuous">
    <parent link="base_link"/>
    <child link="right_wheel"/>
    <origin xyz="-0.1 -0.175 0" rpy="-1.5708 0 0"/>
    <axis xyz="0 0 1"/>
  </joint>

  <!-- Caster Wheel (passive, frictionless) -->
  <link name="caster_wheel">
    <inertial>
      <mass value="0.2"/>
      <inertia ixx="0.0001" ixy="0.0" ixz="0.0"
                             iyy="0.0001" iyz="0.0"
                                          izz="0.0001"/>
    </inertial>
    <visual>
      <geometry>
        <sphere radius="0.05"/>
      </geometry>
      <material name="black"/>
    </visual>
    <collision>
      <geometry>
        <sphere radius="0.05"/>
      </geometry>
    </collision>
  </link>

  <joint name="caster_wheel_joint" type="fixed">
    <parent link="base_link"/>
    <child link="caster_wheel"/>
    <origin xyz="0.15 0 -0.05" rpy="0 0 0"/>
  </joint>

  <gazebo reference="caster_wheel">
    <mu1>0.0</mu1>
    <mu2>0.0</mu2>
  </gazebo>


  <!-- ==================== SENSORS ==================== -->

  <!-- LiDAR -->
  <link name="lidar_link">
    <inertial>
      <mass value="0.1"/>
      <inertia ixx="0.0001" ixy="0.0" ixz="0.0"
                             iyy="0.0001" iyz="0.0"
                                          izz="0.0001"/>
    </inertial>
    <visual>
      <geometry>
        <cylinder radius="0.05" length="0.04"/>
      </geometry>
      <material name="blue"/>
    </visual>
    <collision>
      <geometry>
        <cylinder radius="0.05" length="0.04"/>
      </geometry>
    </collision>
  </link>

  <joint name="lidar_joint" type="fixed">
    <parent link="base_link"/>
    <child link="lidar_link"/>
    <origin xyz="0 0 0.15" rpy="0 0 0"/>
  </joint>

  <!-- IMU -->
  <link name="imu_link">
    <inertial>
      <mass value="0.05"/>
      <inertia ixx="0.00001" ixy="0.0" ixz="0.0"
                              iyy="0.00001" iyz="0.0"
                                            izz="0.00001"/>
    </inertial>
    <visual>
      <geometry>
        <box size="0.02 0.02 0.02"/>
      </geometry>
      <material name="blue"/>
    </visual>
    <collision>
      <geometry>
        <box size="0.02 0.02 0.02"/>
      </geometry>
    </collision>
  </link>

  <joint name="imu_joint" type="fixed">
    <parent link="base_link"/>
    <child link="imu_link"/>
    <origin xyz="0 0 0.08" rpy="0 0 0"/>
  </joint>

  <link name="camera_link">
    <inertial>
    <mass value="0.05"/>
    <inertia ixx="0.00001" ixy="0.0" ixz="0.0" iyy="0.00001" iyz="0.0" izz="0.00001"/>
    </inertial>
    <visual>
    <geometry>
    <box size="0.02 0.06 0.02"/>
    </geometry>
    <material name="blue"/>
    </visual>
    <collision>
    <geometry>
    <box size="0.02 0.06 0.02"/>
    </geometry>
    </collision>
  </link>
    <joint name="camera_joint" type="fixed">
      <parent link="base_link"/>
      <child link="camera_link"/>
      <!-- Mounted at front-center, elevated -->
      <origin xyz="0.2 0 0.1" rpy="0 0 0"/>
    </joint>
    <!--
    Optical frame (ROS convention: Z forward, X right, Y down) 
    -->
  <link name="camera_optical_link"/>
  <joint name="camera_optical_joint" type="fixed">
     <parent link="camera_link"/>
     <child link="camera_optical_link"/>
    <origin xyz="0 0 0" rpy="-1.5708 0 -1.5708"/>
  </joint>


  <!-- ==================== GAZEBO PLUGINS ==================== -->

  <!-- Differential Drive Controller -->
  <gazebo>
    <plugin filename="libignition-gazebo-diff-drive-system.so"
            name="ignition::gazebo::systems::DiffDrive">
      <left_joint>left_wheel_joint</left_joint>
      <right_joint>right_wheel_joint</right_joint>
      <wheel_separation>0.35</wheel_separation>
      <wheel_radius>0.1</wheel_radius>
      <odom_publish_frequency>50</odom_publish_frequency>
      <topic>/cmd_vel</topic>
      <odom_topic>/odom</odom_topic>
      <frame_id>odom</frame_id>
      <child_frame_id>base_footprint</child_frame_id>
    </plugin>
    <plugin filename="libignition-gazebo-pose-publisher-system.so"
            name="ignition::gazebo::systems::PosePublisher">
      <publish_link_pose>true</publish_link_pose>
      <publish_collision_pose>false</publish_collision_pose>
      <publish_visual_pose>false</publish_visual_pose>
      <publish_nested_model_pose>true</publish_nested_model_pose>
      <use_pose_vector_msg>false</use_pose_vector_msg>
      <update_frequency>50</update_frequency>
    </plugin>
  </gazebo>

  <!-- Joint State Publisher -->
  <gazebo>
    <plugin filename="libignition-gazebo-joint-state-publisher-system.so"
            name="ignition::gazebo::systems::JointStatePublisher">
      <topic>/joint_states</topic>
    </plugin>
    <plugin filename="libignition-gazebo-imu-system.so"
        name="ignition::gazebo::systems::Imu">
    </plugin>
  </gazebo>

  <!-- Left Wheel: Realistic Rubber Physics -->
  <gazebo reference="left_wheel">
    <mu1>0.8</mu1>        <!-- Friction parallel to the wheel (forward grip) -->
    <mu2>0.8</mu2>        <!-- Friction perpendicular to the wheel (lateral grip) -->
    <kp>500000.0</kp>     <!-- Contact stiffness: acts as the "squish" of the tire rubber -->
    <kd>10.0</kd>         <!-- Contact damping: absorbs micro-bounces so the wheel stays on the ground -->
    <minDepth>0.001</minDepth> <!-- Simulates a 1mm flat contact patch under the robot's weight -->
  </gazebo>

  <!-- Right Wheel: Realistic Rubber Physics -->
  <gazebo reference="right_wheel">
    <mu1>0.8</mu1>
    <mu2>0.8</mu2>
    <kp>500000.0</kp>
    <kd>10.0</kd>
    <minDepth>0.001</minDepth>
  </gazebo>

  <!-- LiDAR Sensor -->
  <gazebo reference="lidar_link">
    <sensor name="lidar" type="gpu_lidar">
      <always_on>1</always_on>
      <visualize>true</visualize>
      <update_rate>10</update_rate>
      <topic>/scan</topic>
      <ignition_frame_id>lidar_link</ignition_frame_id>
      <ray>
        <scan>
          <horizontal>
            <samples>360</samples>
            <resolution>1.0</resolution>
            <min_angle>-3.14159</min_angle>
            <max_angle>3.14159</max_angle>
          </horizontal>
        </scan>
        <range>
          <min>0.15</min>
          <max>30.0</max>
          <resolution>0.015</resolution>
        </range>
      </ray>
    </sensor>
  </gazebo>

  <!-- IMU Sensor -->
  <gazebo reference="imu_link">
    <sensor name="imu_sensor" type="imu">
      <always_on>1</always_on>
      <update_rate>100</update_rate>
      <topic>/imu</topic> 
      <ignition_frame_id>imu_link</ignition_frame_id>
      <imu>
        <orientation_reference_frame>
          <localization>ENU</localization>
        </orientation_reference_frame>
        <angular_velocity>
          <x><noise type="gaussian"><mean>0.0</mean><stddev>0.0002</stddev></noise></x>
          <y><noise type="gaussian"><mean>0.0</mean><stddev>0.0002</stddev></noise></y>
          <z><noise type="gaussian"><mean>0.0</mean><stddev>0.0002</stddev></noise></z>
        </angular_velocity>
        <linear_acceleration>
          <x><noise type="gaussian"><mean>0.0</mean><stddev>0.017</stddev></noise></x>
          <y><noise type="gaussian"><mean>0.0</mean><stddev>0.017</stddev></noise></y>
          <z><noise type="gaussian"><mean>0.0</mean><stddev>0.017</stddev></noise></z>
        </linear_acceleration>
      </imu>
    </sensor>
  </gazebo>

  <gazebo reference="camera_link">
    <sensor name="camera" type="camera">
    <always_on>1</always_on>
    <update_rate>30</update_rate>
    <topic>/camera/image_raw</topic>
    <ignition_frame_id>camera_optical_link</ignition_frame_id>
    <camera>
    <!-- ~80 degrees -->
    <horizontal_fov>1.3962634</horizontal_fov>
    <image>
    <width>640</width>
    <height>480</height>
    <format>R8G8B8</format>
    </image>
    <clip>
    <near>0.02</near>
    <far>300</far>
    </clip>
    </camera>
    </sensor>
  </gazebo>

</robot>